Workbook

Sheet README
A1: Colistin resistant E. coli genomes from Africa in NCBI Pathogen Detection (v2, 127 genomes)
A2: Source: NCBI Pathogen Detection build PDG000000004.6345 (published 2026-10-06), per-isolate metadata table retrieved in full and country assigned locally. Supersedes the v1 cohort of 118 genomes, which was retrieved on 26 September 2026 by filtering on a 45-name African country list at query time; that list omitted nine of the 54 African Union member states, including South Africa, the Central African Republic and the Democratic Republic of the Congo, and nine genomes were missed as a result. All 118 v1 genomes are retained here and none was dropped.
A3: Source: NCBI Pathogen Detection Isolates Browser (https://www.ncbi.nlm.nih.gov/pathogens/isolates/), queried 26 September 2026.
A4: SRA run accessions were linked to each BioSample through NCBI E-utilities (esearch/esummary, db=sra) on the same date.
A5: Query: taxgroup_name:"E.coli and Shigella" AND AMR_genotypes:mcr* AND geo_loc_name matching any of 45 African country names (wildcard).
A6: Resistance genotypes are the AMRFinderPlus calls computed by NCBI. Intrinsic E. coli genes (acrF, blaEC, mdtM, emrD, emrE, mrx(A)) were removed for readability; point mutations were kept.
A8: Sheets
A9: Isolates: one row per genome (118). Columns in yellow (ST, mcr plasmid replicon, notes) are for you to fill from the Galaxy MLST and PlasmidFinder output.
A10: SRA_runs_for_Galaxy: Illumina paired-end runs to paste into the Galaxy "Faster Download and Extract Reads in FASTQ" tool, plus long-read runs listed separately.
A11: Summary: live COUNTIFS tables by country, sector and mcr variant. They update if you edit the Isolates sheet.
A13: Derived fields and caveats
A14: Sector was assigned from the submitted host and isolation source: Poultry (Gallus, chicken, poultry farm, poultry water, chicken meat/carcass/offal/faeces), Human (Homo sapiens), Other animal (cat, starling), Food non-poultry (unspecified meat, raw milk cheese, sausage), Environment (wastewater, bathing water), Unspecified (no usable metadata).
... A25: Reconciliation (4 October 2026): every filled cell in Isolates (ST, mcr replicon) and every typing and QC column in Galaxy_results was compared by script with the Galaxy outputs re-downloaded from history "mcr Africa C typing" (collapsed AMRFinderPlus, PlasmidFinder and MOB-Recon tables, the explicit-scheme MLST run, QUAST reports and fastp JSON). 118 of 118 genomes matched. The Galaxy_results sheet was rebuilt from those outputs after a column offset was found in the earlier version. The Summary ST and replicon tables were recounted independently and matched.

Sheet Summary
A1: Analysed genomes by country and sector (126 of the 127 retrieved; GCA_015208565.1 excluded at quality control)
A2: Country | B2: Poultry | C2: Human | D2: Other animal | E2: Food (non-poultry) | F2: Environment | G2: Unspecified | H2: Total | I2: With Illumina reads
A3: Algeria | B3: =COUNTIFS(Isolates!$I$2:$I$128,$A3,Isolates!$O$2:$O$128,B$2,Isolates!$AG$2:$AG$128,"Yes") | C3: =COUNTIFS(Isolates!$I$2:$I$128,$A3,Isolates!$O$2:$O$128,C$2,Isolates!$AG$2:$AG$128,"Yes") | D3: =COUNTIFS(Isolates!$I$2:$I$128,$A3,Isolates!$O$2:$O$128,D$2,Isolates!$AG$2:$AG$128,"Yes") | E3: =COUNTIFS(Isolates!$I$2:$I$128,$A3,Isolates!$O$2:$O$128,E$2,Isolates!$AG$2:$AG$128,"Yes") | F3: =COUNTIFS(Isolates!$I$2:$I$128,$A3,Isolates!$O$2:$O$128,F$2,Isolates!$AG$2:$AG$128,"Yes") | G3: =COUNTIFS(Isolates!$I$2:$I$128,$A3,Isolates!$O$2:$O$128,G$2,Isolates!$AG$2:$AG$128,"Yes") | H3: =SUM(B3:G3) | I3: =COUNTIFS(Isolates!$I$2:$I$128,$A3,Isolates!$G$2:$G$128,"SRA Illumina PE reads",Isolates!$AG$2:$AG$128,"Yes")
A4: Cameroon | B4: =COUNTIFS(Isolates!$I$2:$I$128,$A4,Isolates!$O$2:$O$128,B$2,Isolates!$AG$2:$AG$128,"Yes") | C4: =COUNTIFS(Isolates!$I$2:$I$128,$A4,Isolates!$O$2:$O$128,C$2,Isolates!$AG$2:$AG$128,"Yes") | D4: =COUNTIFS(Isolates!$I$2:$I$128,$A4,Isolates!$O$2:$O$128,D$2,Isolates!$AG$2:$AG$128,"Yes") | E4: =COUNTIFS(Isolates!$I$2:$I$128,$A4,Isolates!$O$2:$O$128,E$2,Isolates!$AG$2:$AG$128,"Yes") | F4: =COUNTIFS(Isolates!$I$2:$I$128,$A4,Isolates!$O$2:$O$128,F$2,Isolates!$AG$2:$AG$128,"Yes") | G4: =COUNTIFS(Isolates!$I$2:$I$128,$A4,Isolates!$O$2:$O$128,G$2,Isolates!$AG$2:$AG$128,"Yes") | H4: =SUM(B4:G4) | I4: =COUNTIFS(Isolates!$I$2:$I$128,$A4,Isolates!$G$2:$G$128,"SRA Illumina PE reads",Isolates!$AG$2:$AG$128,"Yes")
A5: Central African Republic | B5: =COUNTIFS(Isolates!$I$2:$I$128,$A5,Isolates!$O$2:$O$128,B$2,Isolates!$AG$2:$AG$128,"Yes") | C5: =COUNTIFS(Isolates!$I$2:$I$128,$A5,Isolates!$O$2:$O$128,C$2,Isolates!$AG$2:$AG$128,"Yes") | D5: =COUNTIFS(Isolates!$I$2:$I$128,$A5,Isolates!$O$2:$O$128,D$2,Isolates!$AG$2:$AG$128,"Yes") | E5: =COUNTIFS(Isolates!$I$2:$I$128,$A5,Isolates!$O$2:$O$128,E$2,Isolates!$AG$2:$AG$128,"Yes") | F5: =COUNTIFS(Isolates!$I$2:$I$128,$A5,Isolates!$O$2:$O$128,F$2,Isolates!$AG$2:$AG$128,"Yes") | G5: =COUNTIFS(Isolates!$I$2:$I$128,$A5,Isolates!$O$2:$O$128,G$2,Isolates!$AG$2:$AG$128,"Yes") | H5: =SUM(B5:G5) | I5: =COUNTIFS(Isolates!$I$2:$I$128,$A5,Isolates!$G$2:$G$128,"SRA Illumina PE reads",Isolates!$AG$2:$AG$128,"Yes")
A6: Democratic Republic of the Congo | B6: =COUNTIFS(Isolates!$I$2:$I$128,$A6,Isolates!$O$2:$O$128,B$2,Isolates!$AG$2:$AG$128,"Yes") | C6: =COUNTIFS(Isolates!$I$2:$I$128,$A6,Isolates!$O$2:$O$128,C$2,Isolates!$AG$2:$AG$128,"Yes") | D6: =COUNTIFS(Isolates!$I$2:$I$128,$A6,Isolates!$O$2:$O$128,D$2,Isolates!$AG$2:$AG$128,"Yes") | E6: =COUNTIFS(Isolates!$I$2:$I$128,$A6,Isolates!$O$2:$O$128,E$2,Isolates!$AG$2:$AG$128,"Yes") | F6: =COUNTIFS(Isolates!$I$2:$I$128,$A6,Isolates!$O$2:$O$128,F$2,Isolates!$AG$2:$AG$128,"Yes") | G6: =COUNTIFS(Isolates!$I$2:$I$128,$A6,Isolates!$O$2:$O$128,G$2,Isolates!$AG$2:$AG$128,"Yes") | H6: =SUM(B6:G6) | I6: =COUNTIFS(Isolates!$I$2:$I$128,$A6,Isolates!$G$2:$G$128,"SRA Illumina PE reads",Isolates!$AG$2:$AG$128,"Yes")
A7: Egypt | B7: =COUNTIFS(Isolates!$I$2:$I$128,$A7,Isolates!$O$2:$O$128,B$2,Isolates!$AG$2:$AG$128,"Yes") | C7: =COUNTIFS(Isolates!$I$2:$I$128,$A7,Isolates!$O$2:$O$128,C$2,Isolates!$AG$2:$AG$128,"Yes") | D7: =COUNTIFS(Isolates!$I$2:$I$128,$A7,Isolates!$O$2:$O$128,D$2,Isolates!$AG$2:$AG$128,"Yes") | E7: =COUNTIFS(Isolates!$I$2:$I$128,$A7,Isolates!$O$2:$O$128,E$2,Isolates!$AG$2:$AG$128,"Yes") | F7: =COUNTIFS(Isolates!$I$2:$I$128,$A7,Isolates!$O$2:$O$128,F$2,Isolates!$AG$2:$AG$128,"Yes") | G7: =COUNTIFS(Isolates!$I$2:$I$128,$A7,Isolates!$O$2:$O$128,G$2,Isolates!$AG$2:$AG$128,"Yes") | H7: =SUM(B7:G7) | I7: =COUNTIFS(Isolates!$I$2:$I$128,$A7,Isolates!$G$2:$G$128,"SRA Illumina PE reads",Isolates!$AG$2:$AG$128,"Yes")
A8: Ethiopia | B8: =COUNTIFS(Isolates!$I$2:$I$128,$A8,Isolates!$O$2:$O$128,B$2,Isolates!$AG$2:$AG$128,"Yes") | C8: =COUNTIFS(Isolates!$I$2:$I$128,$A8,Isolates!$O$2:$O$128,C$2,Isolates!$AG$2:$AG$128,"Yes") | D8: =COUNTIFS(Isolates!$I$2:$I$128,$A8,Isolates!$O$2:$O$128,D$2,Isolates!$AG$2:$AG$128,"Yes") | E8: =COUNTIFS(Isolates!$I$2:$I$128,$A8,Isolates!$O$2:$O$128,E$2,Isolates!$AG$2:$AG$128,"Yes") | F8: =COUNTIFS(Isolates!$I$2:$I$128,$A8,Isolates!$O$2:$O$128,F$2,Isolates!$AG$2:$AG$128,"Yes") | G8: =COUNTIFS(Isolates!$I$2:$I$128,$A8,Isolates!$O$2:$O$128,G$2,Isolates!$AG$2:$AG$128,"Yes") | H8: =SUM(B8:G8) | I8: =COUNTIFS(Isolates!$I$2:$I$128,$A8,Isolates!$G$2:$G$128,"SRA Illumina PE reads",Isolates!$AG$2:$AG$128,"Yes")
A9: Malawi | B9: =COUNTIFS(Isolates!$I$2:$I$128,$A9,Isolates!$O$2:$O$128,B$2,Isolates!$AG$2:$AG$128,"Yes") | C9: =COUNTIFS(Isolates!$I$2:$I$128,$A9,Isolates!$O$2:$O$128,C$2,Isolates!$AG$2:$AG$128,"Yes") | D9: =COUNTIFS(Isolates!$I$2:$I$128,$A9,Isolates!$O$2:$O$128,D$2,Isolates!$AG$2:$AG$128,"Yes") | E9: =COUNTIFS(Isolates!$I$2:$I$128,$A9,Isolates!$O$2:$O$128,E$2,Isolates!$AG$2:$AG$128,"Yes") | F9: =COUNTIFS(Isolates!$I$2:$I$128,$A9,Isolates!$O$2:$O$128,F$2,Isolates!$AG$2:$AG$128,"Yes") | G9: =COUNTIFS(Isolates!$I$2:$I$128,$A9,Isolates!$O$2:$O$128,G$2,Isolates!$AG$2:$AG$128,"Yes") | H9: =SUM(B9:G9) | I9: =COUNTIFS(Isolates!$I$2:$I$128,$A9,Isolates!$G$2:$G$128,"SRA Illumina PE reads",Isolates!$AG$2:$AG$128,"Yes")
A10: Morocco | B10: =COUNTIFS(Isolates!$I$2:$I$128,$A10,Isolates!$O$2:$O$128,B$2,Isolates!$AG$2:$AG$128,"Yes") | C10: =COUNTIFS(Isolates!$I$2:$I$128,$A10,Isolates!$O$2:$O$128,C$2,Isolates!$AG$2:$AG$128,"Yes") | D10: =COUNTIFS(Isolates!$I$2:$I$128,$A10,Isolates!$O$2:$O$128,D$2,Isolates!$AG$2:$AG$128,"Yes") | E10: =COUNTIFS(Isolates!$I$2:$I$128,$A10,Isolates!$O$2:$O$128,E$2,Isolates!$AG$2:$AG$128,"Yes") | F10: =COUNTIFS(Isolates!$I$2:$I$128,$A10,Isolates!$O$2:$O$128,F$2,Isolates!$AG$2:$AG$128,"Yes") | G10: =COUNTIFS(Isolates!$I$2:$I$128,$A10,Isolates!$O$2:$O$128,G$2,Isolates!$AG$2:$AG$128,"Yes") | H10: =SUM(B10:G10) | I10: =COUNTIFS(Isolates!$I$2:$I$128,$A10,Isolates!$G$2:$G$128,"SRA Illumina PE reads",Isolates!$AG$2:$AG$128,"Yes")
A11: Niger | B11: =COUNTIFS(Isolates!$I$2:$I$128,$A11,Isolates!$O$2:$O$128,B$2,Isolates!$AG$2:$AG$128,"Yes") | C11: =COUNTIFS(Isolates!$I$2:$I$128,$A11,Isolates!$O$2:$O$128,C$2,Isolates!$AG$2:$AG$128,"Yes") | D11: =COUNTIFS(Isolates!$I$2:$I$128,$A11,Isolates!$O$2:$O$128,D$2,Isolates!$AG$2:$AG$128,"Yes") | E11: =COUNTIFS(Isolates!$I$2:$I$128,$A11,Isolates!$O$2:$O$128,E$2,Isolates!$AG$2:$AG$128,"Yes") | F11: =COUNTIFS(Isolates!$I$2:$I$128,$A11,Isolates!$O$2:$O$128,F$2,Isolates!$AG$2:$AG$128,"Yes") | G11: =COUNTIFS(Isolates!$I$2:$I$128,$A11,Isolates!$O$2:$O$128,G$2,Isolates!$AG$2:$AG$128,"Yes") | H11: =SUM(B11:G11) | I11: =COUNTIFS(Isolates!$I$2:$I$128,$A11,Isolates!$G$2:$G$128,"SRA Illumina PE reads",Isolates!$AG$2:$AG$128,"Yes")
A12: Nigeria | B12: =COUNTIFS(Isolates!$I$2:$I$128,$A12,Isolates!$O$2:$O$128,B$2,Isolates!$AG$2:$AG$128,"Yes") | C12: =COUNTIFS(Isolates!$I$2:$I$128,$A12,Isolates!$O$2:$O$128,C$2,Isolates!$AG$2:$AG$128,"Yes") | D12: =COUNTIFS(Isolates!$I$2:$I$128,$A12,Isolates!$O$2:$O$128,D$2,Isolates!$AG$2:$AG$128,"Yes") | E12: =COUNTIFS(Isolates!$I$2:$I$128,$A12,Isolates!$O$2:$O$128,E$2,Isolates!$AG$2:$AG$128,"Yes") | F12: =COUNTIFS(Isolates!$I$2:$I$128,$A12,Isolates!$O$2:$O$128,F$2,Isolates!$AG$2:$AG$128,"Yes") | G12: =COUNTIFS(Isolates!$I$2:$I$128,$A12,Isolates!$O$2:$O$128,G$2,Isolates!$AG$2:$AG$128,"Yes") | H12: =SUM(B12:G12) | I12: =COUNTIFS(Isolates!$I$2:$I$128,$A12,Isolates!$G$2:$G$128,"SRA Illumina PE reads",Isolates!$AG$2:$AG$128,"Yes")
A13: Rwanda | B13: =COUNTIFS(Isolates!$I$2:$I$128,$A13,Isolates!$O$2:$O$128,B$2,Isolates!$AG$2:$AG$128,"Yes") | C13: =COUNTIFS(Isolates!$I$2:$I$128,$A13,Isolates!$O$2:$O$128,C$2,Isolates!$AG$2:$AG$128,"Yes") | D13: =COUNTIFS(Isolates!$I$2:$I$128,$A13,Isolates!$O$2:$O$128,D$2,Isolates!$AG$2:$AG$128,"Yes") | E13: =COUNTIFS(Isolates!$I$2:$I$128,$A13,Isolates!$O$2:$O$128,E$2,Isolates!$AG$2:$AG$128,"Yes") | F13: =COUNTIFS(Isolates!$I$2:$I$128,$A13,Isolates!$O$2:$O$128,F$2,Isolates!$AG$2:$AG$128,"Yes") | G13: =COUNTIFS(Isolates!$I$2:$I$128,$A13,Isolates!$O$2:$O$128,G$2,Isolates!$AG$2:$AG$128,"Yes") | H13: =SUM(B13:G13) | I13: =COUNTIFS(Isolates!$I$2:$I$128,$A13,Isolates!$G$2:$G$128,"SRA Illumina PE reads",Isolates!$AG$2:$AG$128,"Yes")
A14: South Africa | B14: =COUNTIFS(Isolates!$I$2:$I$128,$A14,Isolates!$O$2:$O$128,B$2,Isolates!$AG$2:$AG$128,"Yes") | C14: =COUNTIFS(Isolates!$I$2:$I$128,$A14,Isolates!$O$2:$O$128,C$2,Isolates!$AG$2:$AG$128,"Yes") | D14: =COUNTIFS(Isolates!$I$2:$I$128,$A14,Isolates!$O$2:$O$128,D$2,Isolates!$AG$2:$AG$128,"Yes") | E14: =COUNTIFS(Isolates!$I$2:$I$128,$A14,Isolates!$O$2:$O$128,E$2,Isolates!$AG$2:$AG$128,"Yes") | F14: =COUNTIFS(Isolates!$I$2:$I$128,$A14,Isolates!$O$2:$O$128,F$2,Isolates!$AG$2:$AG$128,"Yes") | G14: =COUNTIFS(Isolates!$I$2:$I$128,$A14,Isolates!$O$2:$O$128,G$2,Isolates!$AG$2:$AG$128,"Yes") | H14: =SUM(B14:G14) | I14: =COUNTIFS(Isolates!$I$2:$I$128,$A14,Isolates!$G$2:$G$128,"SRA Illumina PE reads",Isolates!$AG$2:$AG$128,"Yes")
... A18: Uganda | B18: =COUNTIFS(Isolates!$I$2:$I$128,$A18,Isolates!$O$2:$O$128,B$2,Isolates!$AG$2:$AG$128,"Yes") | C18: =COUNTIFS(Isolates!$I$2:$I$128,$A18,Isolates!$O$2:$O$128,C$2,Isolates!$AG$2:$AG$128,"Yes") | D18: =COUNTIFS(Isolates!$I$2:$I$128,$A18,Isolates!$O$2:$O$128,D$2,Isolates!$AG$2:$AG$128,"Yes") | E18: =COUNTIFS(Isolates!$I$2:$I$128,$A18,Isolates!$O$2:$O$128,E$2,Isolates!$AG$2:$AG$128,"Yes") | F18: =COUNTIFS(Isolates!$I$2:$I$128,$A18,Isolates!$O$2:$O$128,F$2,Isolates!$AG$2:$AG$128,"Yes") | G18: =COUNTIFS(Isolates!$I$2:$I$128,$A18,Isolates!$O$2:$O$128,G$2,Isolates!$AG$2:$AG$128,"Yes") | H18: =SUM(B18:G18) | I18: =COUNTIFS(Isolates!$I$2:$I$128,$A18,Isolates!$G$2:$G$128,"SRA Illumina PE reads",Isolates!$AG$2:$AG$128,"Yes")
A19: Total | B19: =SUM(B3:B18) | C19: =SUM(C3:C18) | D19: =SUM(D3:D18) | E19: =SUM(E3:E18) | F19: =SUM(F3:F18) | G19: =SUM(G3:G18) | H19: =SUM(H3:H18) | I19: =SUM(I3:I18)
A21: Analysed genomes by mcr variant and sector (a genome with two variants is counted under each)
A22: mcr variant | B22: Poultry | C22: Human | D22: Other animal | E22: Food (non-poultry) | F22: Environment | G22: Unspecified | H22: Total
A23: mcr-1 | B23: =COUNTIFS(Isolates!$AC$2:$AC$128,"*|"&$A23&"|*",Isolates!$O$2:$O$128,B$22,Isolates!$AG$2:$AG$128,"Yes") | C23: =COUNTIFS(Isolates!$AC$2:$AC$128,"*|"&$A23&"|*",Isolates!$O$2:$O$128,C$22,Isolates!$AG$2:$AG$128,"Yes") | D23: =COUNTIFS(Isolates!$AC$2:$AC$128,"*|"&$A23&"|*",Isolates!$O$2:$O$128,D$22,Isolates!$AG$2:$AG$128,"Yes") | E23: =COUNTIFS(Isolates!$AC$2:$AC$128,"*|"&$A23&"|*",Isolates!$O$2:$O$128,E$22,Isolates!$AG$2:$AG$128,"Yes") | F23: =COUNTIFS(Isolates!$AC$2:$AC$128,"*|"&$A23&"|*",Isolates!$O$2:$O$128,F$22,Isolates!$AG$2:$AG$128,"Yes") | G23: =COUNTIFS(Isolates!$AC$2:$AC$128,"*|"&$A23&"|*",Isolates!$O$2:$O$128,G$22,Isolates!$AG$2:$AG$128,"Yes") | H23: =SUM(B23:G23)
A24: mcr-1.1 | B24: =COUNTIFS(Isolates!$AC$2:$AC$128,"*|"&$A24&"|*",Isolates!$O$2:$O$128,B$22,Isolates!$AG$2:$AG$128,"Yes") | C24: =COUNTIFS(Isolates!$AC$2:$AC$128,"*|"&$A24&"|*",Isolates!$O$2:$O$128,C$22,Isolates!$AG$2:$AG$128,"Yes") | D24: =COUNTIFS(Isolates!$AC$2:$AC$128,"*|"&$A24&"|*",Isolates!$O$2:$O$128,D$22,Isolates!$AG$2:$AG$128,"Yes") | E24: =COUNTIFS(Isolates!$AC$2:$AC$128,"*|"&$A24&"|*",Isolates!$O$2:$O$128,E$22,Isolates!$AG$2:$AG$128,"Yes") | F24: =COUNTIFS(Isolates!$AC$2:$AC$128,"*|"&$A24&"|*",Isolates!$O$2:$O$128,F$22,Isolates!$AG$2:$AG$128,"Yes") | G24: =COUNTIFS(Isolates!$AC$2:$AC$128,"*|"&$A24&"|*",Isolates!$O$2:$O$128,G$22,Isolates!$AG$2:$AG$128,"Yes") | H24: =SUM(B24:G24)
A25: mcr-1.5 | B25: =COUNTIFS(Isolates!$AC$2:$AC$128,"*|"&$A25&"|*",Isolates!$O$2:$O$128,B$22,Isolates!$AG$2:$AG$128,"Yes") | C25: =COUNTIFS(Isolates!$AC$2:$AC$128,"*|"&$A25&"|*",Isolates!$O$2:$O$128,C$22,Isolates!$AG$2:$AG$128,"Yes") | D25: =COUNTIFS(Isolates!$AC$2:$AC$128,"*|"&$A25&"|*",Isolates!$O$2:$O$128,D$22,Isolates!$AG$2:$AG$128,"Yes") | E25: =COUNTIFS(Isolates!$AC$2:$AC$128,"*|"&$A25&"|*",Isolates!$O$2:$O$128,E$22,Isolates!$AG$2:$AG$128,"Yes") | F25: =COUNTIFS(Isolates!$AC$2:$AC$128,"*|"&$A25&"|*",Isolates!$O$2:$O$128,F$22,Isolates!$AG$2:$AG$128,"Yes") | G25: =COUNTIFS(Isolates!$AC$2:$AC$128,"*|"&$A25&"|*",Isolates!$O$2:$O$128,G$22,Isolates!$AG$2:$AG$128,"Yes") | H25: =SUM(B25:G25)
A26: mcr-9 | B26: =COUNTIFS(Isolates!$AC$2:$AC$128,"*|"&$A26&"|*",Isolates!$O$2:$O$128,B$22,Isolates!$AG$2:$AG$128,"Yes") | C26: =COUNTIFS(Isolates!$AC$2:$AC$128,"*|"&$A26&"|*",Isolates!$O$2:$O$128,C$22,Isolates!$AG$2:$AG$128,"Yes") | D26: =COUNTIFS(Isolates!$AC$2:$AC$128,"*|"&$A26&"|*",Isolates!$O$2:$O$128,D$22,Isolates!$AG$2:$AG$128,"Yes") | E26: =COUNTIFS(Isolates!$AC$2:$AC$128,"*|"&$A26&"|*",Isolates!$O$2:$O$128,E$22,Isolates!$AG$2:$AG$128,"Yes") | F26: =COUNTIFS(Isolates!$AC$2:$AC$128,"*|"&$A26&"|*",Isolates!$O$2:$O$128,F$22,Isolates!$AG$2:$AG$128,"Yes") | G26: =COUNTIFS(Isolates!$AC$2:$AC$128,"*|"&$A26&"|*",Isolates!$O$2:$O$128,G$22,Isolates!$AG$2:$AG$128,"Yes") | H26: =SUM(B26:G26)
A27: mcr-9.1 | B27: =COUNTIFS(Isolates!$AC$2:$AC$128,"*|"&$A27&"|*",Isolates!$O$2:$O$128,B$22,Isolates!$AG$2:$AG$128,"Yes") | C27: =COUNTIFS(Isolates!$AC$2:$AC$128,"*|"&$A27&"|*",Isolates!$O$2:$O$128,C$22,Isolates!$AG$2:$AG$128,"Yes") | D27: =COUNTIFS(Isolates!$AC$2:$AC$128,"*|"&$A27&"|*",Isolates!$O$2:$O$128,D$22,Isolates!$AG$2:$AG$128,"Yes") | E27: =COUNTIFS(Isolates!$AC$2:$AC$128,"*|"&$A27&"|*",Isolates!$O$2:$O$128,E$22,Isolates!$AG$2:$AG$128,"Yes") | F27: =COUNTIFS(Isolates!$AC$2:$AC$128,"*|"&$A27&"|*",Isolates!$O$2:$O$128,F$22,Isolates!$AG$2:$AG$128,"Yes") | G27: =COUNTIFS(Isolates!$AC$2:$AC$128,"*|"&$A27&"|*",Isolates!$O$2:$O$128,G$22,Isolates!$AG$2:$AG$128,"Yes") | H27: =SUM(B27:G27)
A28: mcr-9.2 | B28: =COUNTIFS(Isolates!$AC$2:$AC$128,"*|"&$A28&"|*",Isolates!$O$2:$O$128,B$22,Isolates!$AG$2:$AG$128,"Yes") | C28: =COUNTIFS(Isolates!$AC$2:$AC$128,"*|"&$A28&"|*",Isolates!$O$2:$O$128,C$22,Isolates!$AG$2:$AG$128,"Yes") | D28: =COUNTIFS(Isolates!$AC$2:$AC$128,"*|"&$A28&"|*",Isolates!$O$2:$O$128,D$22,Isolates!$AG$2:$AG$128,"Yes") | E28: =COUNTIFS(Isolates!$AC$2:$AC$128,"*|"&$A28&"|*",Isolates!$O$2:$O$128,E$22,Isolates!$AG$2:$AG$128,"Yes") | F28: =COUNTIFS(Isolates!$AC$2:$AC$128,"*|"&$A28&"|*",Isolates!$O$2:$O$128,F$22,Isolates!$AG$2:$AG$128,"Yes") | G28: =COUNTIFS(Isolates!$AC$2:$AC$128,"*|"&$A28&"|*",Isolates!$O$2:$O$128,G$22,Isolates!$AG$2:$AG$128,"Yes") | H28: =SUM(B28:G28)
A29: mcr-10.1 | B29: =COUNTIFS(Isolates!$AC$2:$AC$128,"*|"&$A29&"|*",Isolates!$O$2:$O$128,B$22,Isolates!$AG$2:$AG$128,"Yes") | C29: =COUNTIFS(Isolates!$AC$2:$AC$128,"*|"&$A29&"|*",Isolates!$O$2:$O$128,C$22,Isolates!$AG$2:$AG$128,"Yes") | D29: =COUNTIFS(Isolates!$AC$2:$AC$128,"*|"&$A29&"|*",Isolates!$O$2:$O$128,D$22,Isolates!$AG$2:$AG$128,"Yes") | E29: =COUNTIFS(Isolates!$AC$2:$AC$128,"*|"&$A29&"|*",Isolates!$O$2:$O$128,E$22,Isolates!$AG$2:$AG$128,"Yes") | F29: =COUNTIFS(Isolates!$AC$2:$AC$128,"*|"&$A29&"|*",Isolates!$O$2:$O$128,F$22,Isolates!$AG$2:$AG$128,"Yes") | G29: =COUNTIFS(Isolates!$AC$2:$AC$128,"*|"&$A29&"|*",Isolates!$O$2:$O$128,G$22,Isolates!$AG$2:$AG$128,"Yes") | H29: =SUM(B29:G29)
A30: Note: "mcr-1" and "mcr-9" without an allele number are AMRFinderPlus calls where the allele could not be resolved (partial or divergent hit).
A31: Retrieval and quality control
A32: Genomes retrieved for build PDG000000004.6345 | B32: 127
A33: Excluded: CheckM2 contamination above the 5% ceiling | B33: 1 | C33: Poultry farm environment | D33: Poultry drinking water | E33: Poultry meat/carcass | F33: Total
A34: Genomes analysed | B34: 126 | C34: =COUNTIFS(Isolates!$I$2:$I$128,$A34,Isolates!$P$2:$P$128,C$33,Isolates!$AG$2:$AG$128,"Yes") | D34: =COUNTIFS(Isolates!$I$2:$I$128,$A34,Isolates!$P$2:$P$128,D$33,Isolates!$AG$2:$AG$128,"Yes") | E34: =COUNTIFS(Isolates!$I$2:$I$128,$A34,Isolates!$P$2:$P$128,E$33,Isolates!$AG$2:$AG$128,"Yes") | F34: =SUM(B34:E34)
A35: Excluded accession | B35: GCA_015208565.1 (SAMN14219481), 6.00% contamination | C35: =COUNTIFS(Isolates!$I$2:$I$128,$A35,Isolates!$P$2:$P$128,C$33,Isolates!$AG$2:$AG$128,"Yes") | D35: =COUNTIFS(Isolates!$I$2:$I$128,$A35,Isolates!$P$2:$P$128,D$33,Isolates!$AG$2:$AG$128,"Yes") | E35: =COUNTIFS(Isolates!$I$2:$I$128,$A35,Isolates!$P$2:$P$128,E$33,Isolates!$AG$2:$AG$128,"Yes") | F35: =SUM(B35:E35)
A36: Egypt | B36: =COUNTIFS(Isolates!$I$2:$I$128,$A36,Isolates!$P$2:$P$128,B$33,Isolates!$AG$2:$AG$128,"Yes") | C36: =COUNTIFS(Isolates!$I$2:$I$128,$A36,Isolates!$P$2:$P$128,C$33,Isolates!$AG$2:$AG$128,"Yes") | D36: =COUNTIFS(Isolates!$I$2:$I$128,$A36,Isolates!$P$2:$P$128,D$33,Isolates!$AG$2:$AG$128,"Yes") | E36: =COUNTIFS(Isolates!$I$2:$I$128,$A36,Isolates!$P$2:$P$128,E$33,Isolates!$AG$2:$AG$128,"Yes") | F36: =SUM(B36:E36)
A37: Morocco | B37: =COUNTIFS(Isolates!$I$2:$I$128,$A37,Isolates!$P$2:$P$128,B$33,Isolates!$AG$2:$AG$128,"Yes") | C37: =COUNTIFS(Isolates!$I$2:$I$128,$A37,Isolates!$P$2:$P$128,C$33,Isolates!$AG$2:$AG$128,"Yes") | D37: =COUNTIFS(Isolates!$I$2:$I$128,$A37,Isolates!$P$2:$P$128,D$33,Isolates!$AG$2:$AG$128,"Yes") | E37: =COUNTIFS(Isolates!$I$2:$I$128,$A37,Isolates!$P$2:$P$128,E$33,Isolates!$AG$2:$AG$128,"Yes") | F37: =SUM(B37:E37)
A38: Nigeria | B38: =COUNTIFS(Isolates!$I$2:$I$128,$A38,Isolates!$P$2:$P$128,B$33,Isolates!$AG$2:$AG$128,"Yes") | C38: =COUNTIFS(Isolates!$I$2:$I$128,$A38,Isolates!$P$2:$P$128,C$33,Isolates!$AG$2:$AG$128,"Yes") | D38: =COUNTIFS(Isolates!$I$2:$I$128,$A38,Isolates!$P$2:$P$128,D$33,Isolates!$AG$2:$AG$128,"Yes") | E38: =COUNTIFS(Isolates!$I$2:$I$128,$A38,Isolates!$P$2:$P$128,E$33,Isolates!$AG$2:$AG$128,"Yes") | F38: =SUM(B38:E38)
A39: Tanzania | B39: =COUNTIFS(Isolates!$I$2:$I$128,$A39,Isolates!$P$2:$P$128,B$33,Isolates!$AG$2:$AG$128,"Yes") | C39: =COUNTIFS(Isolates!$I$2:$I$128,$A39,Isolates!$P$2:$P$128,C$33,Isolates!$AG$2:$AG$128,"Yes") | D39: =COUNTIFS(Isolates!$I$2:$I$128,$A39,Isolates!$P$2:$P$128,D$33,Isolates!$AG$2:$AG$128,"Yes") | E39: =COUNTIFS(Isolates!$I$2:$I$128,$A39,Isolates!$P$2:$P$128,E$33,Isolates!$AG$2:$AG$128,"Yes") | F39: =SUM(B39:E39)
A40: Uganda | B40: =COUNTIFS(Isolates!$I$2:$I$128,$A40,Isolates!$P$2:$P$128,B$33,Isolates!$AG$2:$AG$128,"Yes") | C40: =COUNTIFS(Isolates!$I$2:$I$128,$A40,Isolates!$P$2:$P$128,C$33,Isolates!$AG$2:$AG$128,"Yes") | D40: =COUNTIFS(Isolates!$I$2:$I$128,$A40,Isolates!$P$2:$P$128,D$33,Isolates!$AG$2:$AG$128,"Yes") | E40: =COUNTIFS(Isolates!$I$2:$I$128,$A40,Isolates!$P$2:$P$128,E$33,Isolates!$AG$2:$AG$128,"Yes") | F40: =SUM(B40:E40)
A42: Genomes by sequence type (Achtman) and sector, STs seen in two or more genomes
A43: ST | B43: Poultry | C43: Human | D43: Other animal | E43: Food (non-poultry) | F43: Environment | G43: Unspecified | H43: Total
A44: 46 | B44: =COUNTIFS(Isolates!$Z$2:$Z$128,$A44,Isolates!$O$2:$O$128,B$43,Isolates!$AG$2:$AG$128,"Yes") | C44: =COUNTIFS(Isolates!$Z$2:$Z$128,$A44,Isolates!$O$2:$O$128,C$43,Isolates!$AG$2:$AG$128,"Yes") | D44: =COUNTIFS(Isolates!$Z$2:$Z$128,$A44,Isolates!$O$2:$O$128,D$43,Isolates!$AG$2:$AG$128,"Yes") | E44: =COUNTIFS(Isolates!$Z$2:$Z$128,$A44,Isolates!$O$2:$O$128,E$43,Isolates!$AG$2:$AG$128,"Yes") | F44: =COUNTIFS(Isolates!$Z$2:$Z$128,$A44,Isolates!$O$2:$O$128,F$43,Isolates!$AG$2:$AG$128,"Yes") | G44: =COUNTIFS(Isolates!$Z$2:$Z$128,$A44,Isolates!$O$2:$O$128,G$43,Isolates!$AG$2:$AG$128,"Yes") | H44: =SUM(B44:G44)
A45: 155 | B45: =COUNTIFS(Isolates!$Z$2:$Z$128,$A45,Isolates!$O$2:$O$128,B$43,Isolates!$AG$2:$AG$128,"Yes") | C45: =COUNTIFS(Isolates!$Z$2:$Z$128,$A45,Isolates!$O$2:$O$128,C$43,Isolates!$AG$2:$AG$128,"Yes") | D45: =COUNTIFS(Isolates!$Z$2:$Z$128,$A45,Isolates!$O$2:$O$128,D$43,Isolates!$AG$2:$AG$128,"Yes") | E45: =COUNTIFS(Isolates!$Z$2:$Z$128,$A45,Isolates!$O$2:$O$128,E$43,Isolates!$AG$2:$AG$128,"Yes") | F45: =COUNTIFS(Isolates!$Z$2:$Z$128,$A45,Isolates!$O$2:$O$128,F$43,Isolates!$AG$2:$AG$128,"Yes") | G45: =COUNTIFS(Isolates!$Z$2:$Z$128,$A45,Isolates!$O$2:$O$128,G$43,Isolates!$AG$2:$AG$128,"Yes") | H45: =SUM(B45:G45)
...

Sheet Isolates
A1: PD target | B1: BioSample | C1: BioProject | D1: Assembly (GCA) | E1: SRA Illumina PE run(s) | F1: Long-read run(s) | G1: Recommended Galaxy input | H1: Strain | I1: Country | J1: Sub-national location | K1: Year | L1: Collection date (as submitted) | M1: Host (as submitted) | N1: Isolation source (as submitted) | O1: Sector (derived) | P1: Poultry niche (derived) | Q1: PD epi_type | R1: mcr variant(s) | S1: >1 mcr call | T1: CTX-M allele(s) | U1: Carbapenemase gene(s) | V1: pmrB mutation(s) | W1: Contigs (PD assembly) | X1: No. acquired AMR genes | Y1: AMRFinderPlus genotype (PD, intrinsic genes removed) | Z1: ST (Achtman) - to fill | AA1: Plasmid replicon carrying mcr - to fill | AB1: Notes - to fill | AC1: mcr key (helper) | AD1: CheckM2 completeness (%) | AE1: CheckM2 contamination (%) | AF1: IS30-family element on mcr contig | AG1: Included in analysis | AH1: Reason for exclusion
A2: PDT003403345.1 | B2: SAMEA123453495 | C2: PRJEB126541 | D2: GCA_988286365.1 | G2: GenBank assembly (no reads) | I2: Algeria | K2: 2025 | L2: 2025 | O2: Unspecified | R2: mcr-1.1 | W2: 10 | X2: 15 | Y2: aadA1 aadA2 ant(3'')-Ia aph(3')-Ia blaTEM-1 cmlA1 dfrA12 floR fosA4 gyrA_D87N gyrA_S83L lnu(F) mcr-1.1 mph(A) parC_S80I parE_S458A qnrS1 sul3 tet(A) | Z2: 410 | AA2: IncI2 | AB2: Assembly not in NCBI Datasets; downloaded from ENA (10 contigs, 5.36 Mb). | AC2: |mcr-1.1| | AD2: 100 | AE2: 0.1 | AF2: no | AG2: Yes
A3: PDT003351203.1 | B3: SAMEA115598817 | C3: PRJEB71867 | E3: ERR13133321 | G3: SRA Illumina PE reads | I3: Egypt | K3: 2019 | L3: 2019 | M3: Homo sapiens | N3: human | O3: Human | Q3: clinical | R3: mcr-1.1 | T3: blaCTX-M-14 | U3: blaOXA-48 | W3: 160 | X3: 9 | Y3: aac(3)-IId aph(3'')-Ib aph(6)-Id blaCTX-M-14 blaOXA-48 blaTEM-1 gyrA_D87N gyrA_S83L mcr-1.1 mph(A) parC_S80I parE_S458A tet(A) uhpT_E350Q | Z3: 1196 | AA3: IncX4 | AC3: |mcr-1.1| | AD3: 100 | AE3: 0.16 | AF3: no | AG3: Yes
A4: PDT003351163.1 | B4: SAMEA115598777 | C4: PRJEB71867 | E4: ERR13133281 | G4: SRA Illumina PE reads | I4: Egypt | K4: 2019 | L4: 2019 | M4: Homo sapiens | N4: human | O4: Human | Q4: clinical | R4: mcr-1.1 | T4: blaCTX-M-15 | W4: 203 | X4: 11 | Y4: aac(3)-IIe aadA22 aadA5 blaCTX-M-15 blaTEM-1 dfrA17 erm(B) floR gyrA_D87N gyrA_S83L mcr-1.1 mph(A) nfsA_Q72Ter parC_S80I sul1 | Z4: 359 | AA4: Chromosomal or unresolved (MOB-Recon) | AB4: mcr contig only 2,750 bp; bin assignment is tentative. | AC4: |mcr-1.1| | AD4: 100 | AE4: 0.29 | AF4: no | AG4: Yes
A5: PDT003185044.1 | B5: SAMN54240895 | C5: PRJNA1392031 | D5: GCA_056837985.1 | G5: GenBank assembly (no reads) | H5: Eco_70233 | I5: Tunisia | J5: Tunis | K5: 2025 | L5: 2025-02-26 | M5: Homo sapiens | O5: Human | Q5: clinical | R5: mcr-1.1 | W5: 6 | X5: 8 | Y5: aadA2 blaTEM-1 dfrA12 floR gyrA_D87N gyrA_S83L mcr-1.1 mph(A) ompF_W83Ter parC_S80I sul1 tet(A) | Z5: 1011 | AA5: IncX4 | AC5: |mcr-1.1| | AD5: 100 | AE5: 0.73 | AF5: no | AG5: Yes
A6: PDT003185043.1 | B6: SAMN54240896 | C6: PRJNA1392031 | D6: GCA_056837925.1 | G6: GenBank assembly (no reads) | H6: Eco_70234 | I6: Tunisia | J6: Tunis | K6: 2025 | L6: 2025-03-26 | M6: Homo sapiens | O6: Human | Q6: clinical | R6: mcr-1.1 | W6: 4 | X6: 10 | Y6: acrR_E190RfsTer20 aph(3'')-Ib aph(3')-Ia aph(6)-Id blaTEM-1 dfrA14 gyrA_D87N gyrA_S83L mcr-1.1 mph(A) parC_S80I parE_S458A qnrS1 sul2 tet(A) | Z6: 167 | AA6: IncX4 | AC6: |mcr-1.1| | AD6: 100 | AE6: 0.34 | AF6: no | AG6: Yes
A7: PDT003185042.1 | B7: SAMN54240897 | C7: PRJNA1392031 | D7: GCA_056837905.1 | G7: GenBank assembly (no reads) | H7: Eco_70237 | I7: Tunisia | J7: Tunis | K7: 2023 | L7: 2023-08-15 | M7: Homo sapiens | O7: Human | Q7: clinical | R7: mcr-1.1 | T7: blaCTX-M-55 | W7: 6 | X7: 9 | Y7: aadA5 aph(3'')-Ib aph(6)-Id blaCTX-M-55 cirA_G181VfsTer13 cyaA_S352T dfrA17 floR gyrA_D87N gyrA_S83L mcr-1.1 nfsA_R15C parC_S80I parE_S458T sul2 tet(A) | Z7: 117 | AA7: IncI2 | AC7: |mcr-1.1| | AD7: 100 | AE7: 0.23 | AF7: no | AG7: Yes
A8: PDT003185041.1 | B8: SAMN54240898 | C8: PRJNA1392031 | D8: GCA_056837885.1 | G8: GenBank assembly (no reads) | H8: Eco_70238 | I8: Tunisia | J8: Tunis | K8: 2025 | L8: 2025-02-18 | M8: Homo sapiens | O8: Human | Q8: clinical | R8: mcr-1.1 | W8: 6 | X8: 1 | Y8: cyaA_S352T mcr-1.1 nfsA_S33R uhpT_E350Q | Z8: Untypeable | AA8: IncI2 | AB8: Novel or partial MLST allele (adk(203) fumC(~210) gyrB(308) icd(25) mdh(4) purA(16) recA(19)). | AC8: |mcr-1.1| | AD8: 100 | AE8: 0.35 | AF8: no | AG8: Yes
A9: PDT003185040.1 | B9: SAMN54240899 | C9: PRJNA1392031 | D9: GCA_056837865.1 | G9: GenBank assembly (no reads) | H9: Eco_70240 | I9: Tunisia | J9: Tunis | K9: 2023 | L9: 2023-12-27 | M9: Homo sapiens | O9: Human | Q9: clinical | R9: mcr-1.1 | W9: 5 | X9: 4 | Y9: blaTEM-1 blaTEMp_C32T cirA_W164Ter cyaA_S352T dfrA14 gyrA_S83L mcr-1.1 parC_S80I tet(B) | Z9: 69 | AA9: IncI2 | AC9: |mcr-1.1| | AD9: 100 | AE9: 0.69 | AF9: no | AG9: Yes
A10: PDT003185039.1 | B10: SAMN54240900 | C10: PRJNA1392031 | D10: GCA_056837825.1 | G10: GenBank assembly (no reads) | H10: Eco_70242 | I10: Tunisia | J10: Tunis | K10: 2024 | L10: 2024-07-01 | M10: Homo sapiens | O10: Human | Q10: clinical | R10: mcr-1.1 | T10: blaCTX-M-55 | W10: 4 | X10: 9 | Y10: aph(3'')-Ib aph(6)-Id blaCTX-M-55 blaTEM-1 dfrA5 floR gyrA_D87N gyrA_S83L mcr-1.1 parC_S80I sul2 tet(A) | Z10: 9697 | AA10: IncI2 | AC10: |mcr-1.1| | AD10: 100 | AE10: 0.39 | AF10: no | AG10: Yes
A11: PDT003178996.1 | B11: SAMN57053898 | C11: PRJNA1392031 | D11: GCA_056711405.1 | G11: GenBank assembly (no reads) | H11: Eco_70239 | I11: Tunisia | J11: Tunis | K11: 2024 | L11: 2024-09-09 | M11: Homo sapiens | N11: urine | O11: Human | Q11: clinical | R11: mcr-1.1 | T11: blaCTX-M-55 | W11: 6 | X11: 9 | Y11: aph(3'')-Ib aph(6)-Id blaCTX-M-55 blaTEM-1 dfrA5 floR gyrA_D87N gyrA_S83L mcr-1.1 parC_S80I sul2 tet(A) | Z11: 9697 | AA11: IncI2 | AC11: |mcr-1.1| | AD11: 100 | AE11: 0.39 | AF11: no | AG11: Yes
A12: PDT003138659.1 | B12: SAMN47585712 | C12: PRJNA1242317 | D12: GCA_055786625.1 | G12: GenBank assembly (no reads) | H12: ECO150 | I12: Algeria | J12: Batna | K12: 2023 | L12: 2023-10-16 | M12: Felis catus | N12: cat | O12: Other animal | Q12: clinical | R12: mcr-1.1 | T12: blaCTX-M-1 | W12: 5 | X12: 8 | Y12: aph(3')-Ia blaCTX-M-1 blaTEM-1 dfrA14 gyrA_D87N gyrA_S83L mcr-1.1 parC_E84A parC_S80I qnrS1 sul2 tet(A) | Z12: 162 | AA12: IncI2 | AC12: |mcr-1.1| | AD12: 100 | AE12: 0.22 | AF12: no | AG12: Yes
A13: PDT003138657.1 | B13: SAMN47585716 | C13: PRJNA1242317 | D13: GCA_055786575.1 | G13: GenBank assembly (no reads) | H13: ECO164 | I13: Algeria | J13: Batna | K13: 2023 | L13: 2023-11-15 | M13: Felis catus | N13: cat | O13: Other animal | Q13: clinical | R13: mcr-1.1 | T13: blaCTX-M-1 | W13: 5 | X13: 7 | Y13: aph(3')-Ia blaCTX-M-1 dfrA14 mcr-1.1 qnrS1 sul2 tet(A) | Z13: 10 | AA13: IncI2 | AC13: |mcr-1.1| | AD13: 100 | AE13: 0.64 | AF13: no | AG13: Yes
A14: PDT003138653.1 | B14: SAMN47585720 | C14: PRJNA1242317 | D14: GCA_055786505.1 | G14: GenBank assembly (no reads) | H14: ECO187 | I14: Algeria | J14: Batna | K14: 2023 | L14: 2023-11-27 | M14: Felis catus | N14: cat | O14: Other animal | Q14: clinical | R14: mcr-1.1 | T14: blaCTX-M-1 | W14: 4 | X14: 10 | Y14: blaCTX-M-1 blaTEM-1 dfrA14 gyrA_S83L mcr-1.1 mph(A) qnrS1 sul2 sul3 tet(A) tet(A) | Z14: 162 | AA14: IncI2 | AC14: |mcr-1.1| | AD14: 100 | AE14: 0.58 | AF14: no | AG14: Yes
A15: PDT003089479.1 | B15: SAMEA120781931 | C15: PRJEB104706 | D15: GCA_977857605.1 | G15: GenBank assembly (no reads) | I15: Cameroon | K15: 2022 | L15: 2022 | M15: Gallus gallus domesticus | N15: stool | O15: Poultry | P15: Live bird (faeces/cloaca/organ) | R15: mcr-1.1 | T15: blaCTX-M-125 | W15: 166 | X15: 11 | Y15: aadA1 aadA2 blaCTX-M-125 blaTEM-1 cmlA1 dfrA12 gyrA_D87N gyrA_S83L mcr-1.1 parC_S80R qnrS1 sul3 tet(A) tet(M) | Z15: 5625 | AA15: IncHI1A/IncFIA (MOB-Recon bin) | AC15: |mcr-1.1| | AD15: 100 | AE15: 0.06 | AF15: yes | AG15: Yes
A16: PDT003059286.1 | B16: SAMN53123345 | C16: PRJNA1358714 | D16: GCA_054553885.1 | E16: SRR35975911 | G16: SRA Illumina PE reads | I16: Tunisia | J16: Sfax | K16: 2018 | L16: 2018 | M16: Homo sapiens | N16: wound | O16: Human | Q16: clinical | R16: mcr-1.1 | U16: blaOXA-48 | W16: 86 | X16: 10 | Y16: aac(3)-IId aadA2 aph(3'')-Ib aph(6)-Id blaOXA-48 blaTEM-1 cirA_Q65Ter dfrA12 gyrA_D87N gyrA_S83L mcr-1.1 parC_S80I sul2 tet(A) | Z16: 1011 | AA16: IncX4 | AC16: |mcr-1.1| | AD16: 100 | AE16: 0.57 | AF16: no | AG16: Yes
A17: PDT003059285.1 | B17: SAMN53123346 | C17: PRJNA1358714 | D17: GCA_054553805.1 | E17: SRR35975910 | G17: SRA Illumina PE reads | I17: Tunisia | J17: Sfax | K17: 2018 | L17: 2018 | M17: Homo sapiens | N17: wound | O17: Human | Q17: clinical | R17: mcr-1.1 | W17: 151 | X17: 8 | Y17: acrR_P182RfsTer62 aph(3'')-Ib aph(6)-Id blaTEM-1 estT floR gyrA_D87N gyrA_S83L mcr-1.1 parC_S80I sul2 tet(A) | Z17: Untypeable | AA17: IncX4 | AB17: Novel or partial MLST allele (adk(99) fumC(~1179) gyrB(33) icd(33) mdh(24) purA(8) recA(7)). | AC17: |mcr-1.1| | AD17: 100 | AE17: 0.77 | AF17: no | AG17: Yes
A18: PDT003045902.1 | B18: SAMN54331487 | C18: PRJNA1395011 | D18: GCA_054353075.1 | G18: GenBank assembly (no reads) | H18: EC100 | I18: Morocco | K18: 2024 | L18: 2024-05-03 | N18: wastewater | O18: Environment | Q18: environmental/other | R18: mcr-1.1 | T18: blaCTX-M-276 | W18: 177 | X18: 13 | Y18: aac(6')-Ib-cr5 aadA1 aadA2 acrR_E190RfsTer20 blaCTX-M-276 blaOXA-1 blaTEM-1 catB3 cmlA1 estX-3 gyrA_D87N gyrA_S83L mcr-1.1 parC_S80I parE_S458A sul3 tet(A) tet(B) | Z18: 10 | AA18: IncI2 | AC18: |mcr-1.1| | AD18: 100 | AE18: 0.09 | AF18: no | AG18: Yes
A19: PDT003025986.1 | B19: SAMEA115952006 | C19: PRJEB65965 | D19: GCA_058969675.1 | E19: ERR15952774 | G19: SRA Illumina PE reads | H19: DCG156E1 | I19: Malawi | O19: Unspecified | R19: mcr-9 | W19: 137 | X19: 14 | Y19: aac(3)-IIg aac(6')-IIc aadA2 aph(3'')-Ib aph(6)-Id arr blaSHV-12 blaTEM-1 dfrA19 ere(A) mcr-9 qnrB2 sul1 sul2 | Z19: 401 | AA19: IncHI2A (MOB-Recon bin) | AB19: mcr contig only 2,627 bp; bin assignment is tentative. mcr-9 call is BLASTX (100.0% coverage, 99.81% identity); check before counting. | AC19: |mcr-9| | AD19: 100 | AE19: 0.55 | AF19: no | AG19: Yes
A20: PDT002971161.1 | B20: SAMN49661573 | C20: PRJNA1282727 | D20: GCA_053291725.1 | G20: GenBank assembly (no reads) | H20: E3 | I20: Morocco | K20: 2021 | L20: 2021-03-19 | N20: chicken offal | O20: Poultry | P20: Poultry meat/carcass | Q20: environmental/other | R20: mcr-1.1 | W20: 107 | X20: 9 | Y20: aadA2 aph(3')-Ia blaTEM-1 cirA_D46MfsTer21 dfrA12 gyrA_D87N gyrA_S83L mcr-1.1 mph(A) parC_S80I sul1 sul2 tet(A) | Z20: 57 | AA20: IncI2 | AC20: |mcr-1.1| | AD20: 100 | AE20: 0.57 | AF20: no | AG20: Yes
A21: PDT002952003.1 | B21: SAMN44571232 | C21: PRJNA1181821 | D21: GCA_053044365.1 | G21: GenBank assembly (no reads) | H21: 23-MO00583-5 | I21: Uganda | K21: 2022 | L21: 2022 | M21: Poultry | N21: swab | O21: Poultry | P21: Live bird (faeces/cloaca/organ) | R21: mcr-1.1 | W21: 219 | X21: 8 | Y21: aac(3)-IId aph(6)-Id blaTEM-1 dfrA14 mcr-1.1 qnrS1 sul3 tet(A) | Z21: 155 | AA21: IncI2 | AC21: |mcr-1.1| | AD21: 100 | AE21: 0.25 | AF21: no | AG21: Yes
A22: PDT002952002.1 | B22: SAMN44571233 | C22: PRJNA1181821 | D22: GCA_053044345.1 | G22: GenBank assembly (no reads) | H22: 23-MO00719-1 | I22: Uganda | K22: 2022 | L22: 2022 | M22: Poultry | N22: swab | O22: Poultry | P22: Live bird (faeces/cloaca/organ) | R22: mcr-1.1 | V22: pmrB_A159V | W22: 217 | X22: 8 | Y22: aac(3)-IId aph(6)-Id blaTEM-1 dfrA14 mcr-1.1 pmrB_A159V qnrS1 sul3 tet(A) | Z22: 155 | AA22: IncI2 | AC22: |mcr-1.1| | AD22: 100 | AE22: 0.25 | AF22: no | AG22: Yes
A23: PDT002952001.1 | B23: SAMN44571236 | C23: PRJNA1181821 | D23: GCA_053044255.1 | G23: GenBank assembly (no reads) | H23: 23-MO00770-1 | I23: Uganda | K23: 2022 | L23: 2022 | M23: Poultry | N23: swab | O23: Poultry | P23: Live bird (faeces/cloaca/organ) | R23: mcr-1.1 | W23: 207 | X23: 8 | Y23: aac(3)-IId aph(6)-Id blaTEM-1 dfrA14 mcr-1.1 qnrS1 sul3 tet(A) | Z23: 155 | AA23: IncI2 | AC23: |mcr-1.1| | AD23: 100 | AE23: 0.28 | AF23: no | AG23: Yes
A24: PDT002952000.1 | B24: SAMN44571234 | C24: PRJNA1181821 | D24: GCA_053044235.1 | G24: GenBank assembly (no reads) | H24: 23-MO00728-1 | I24: Uganda | K24: 2022 | L24: 2022 | M24: Poultry | N24: swab | O24: Poultry | P24: Live bird (faeces/cloaca/organ) | R24: mcr-1.1 | W24: 205 | X24: 8 | Y24: aac(3)-IId aph(6)-Id blaTEM-1 dfrA14 mcr-1.1 qnrS1 sul3 tet(A) | Z24: 155 | AA24: IncI2 | AC24: |mcr-1.1| | AD24: 100 | AE24: 0.25 | AF24: no | AG24: Yes
A25: PDT002951999.1 | B25: SAMN44571235 | C25: PRJNA1181821 | D25: GCA_053044225.1 | G25: GenBank assembly (no reads) | H25: 23-MO00748-1 | I25: Uganda | K25: 2022 | L25: 2022 | M25: Poultry | N25: swab | O25: Poultry | P25: Live bird (faeces/cloaca/organ) | R25: mcr-1.1 | W25: 232 | X25: 8 | Y25: aac(3)-IId aph(6)-Id blaTEM-1 dfrA14 mcr-1.1 qnrS1 sul3 tet(A) | Z25: 155 | AA25: IncI2 | AC25: |mcr-1.1| | AD25: 100 | AE25: 0.27 | AF25: no | AG25: Yes
A26: PDT002921590.1 | B26: SAMN47596258 | C26: PRJNA1242575 | D26: GCA_052587725.1 | E26: SRR32899019 | G26: SRA Illumina PE reads | H26: 65321 | I26: Tunisia | K26: 2024 | L26: 2024 | N26: meat | O26: Food (non-poultry) | R26: mcr-1.1 | T26: blaCTX-M-1 | W26: 225 | X26: 10 | Y26: aadA1 blaCTX-M-1 catA1 cyaA_S352T dfrA1 floR gyrA_D87N gyrA_S83L mcr-1.1 mph(B) parC_S80I rdmCL sul1 tet(A) | Z26: 3941 | AA26: IncHI2A (MOB-Recon bin) | AB26: mcr contig only 1,761 bp; bin assignment is tentative. mcr-1 call is BLASTX (96.9% coverage, 100.00% identity); check before counting. Galaxy AMRFinderPlus call (mcr-1) differs from PD (mcr-1.1). | AC26: |mcr-1.1| | AD26: 100 | AE26: 0.79 | AF26: no | AG26: Yes
A27: PDT002921586.1 | B27: SAMN47596259 | C27: PRJNA1242575 | D27: GCA_052587645.1 | E27: SRR32899008 | G27: SRA Illumina PE reads | H27: 65324 | I27: Tunisia | K27: 2024 | L27: 2024 | N27: meat | O27: Food (non-poultry) | R27: mcr-1.1 | T27: blaCTX-M-1 | W27: 220 | X27: 10 | Y27: aadA1 blaCTX-M-1 catA1 cyaA_S352T dfrA1 floR gyrA_D87N gyrA_S83L mcr-1.1 mph(B) parC_S80I rdmCL sul1 tet(A) | Z27: 3941 | AA27: IncHI2A (MOB-Recon bin) | AB27: mcr contig only 1,761 bp; bin assignment is tentative. mcr-1 call is BLASTX (96.9% coverage, 100.00% identity); check before counting. Galaxy AMRFinderPlus call (mcr-1) differs from PD (mcr-1.1). | AC27: |mcr-1.1| | AD27: 100 | AE27: 0.76 | AF27: no | AG27: Yes
A28: PDT002921584.1 | B28: SAMN47596263 | C28: PRJNA1242575 | D28: GCA_052587485.1 | E28: SRR32898997 | G28: SRA Illumina PE reads | H28: 65334 | I28: Tunisia | K28: 2024 | L28: 2024 | M28: meat | O28: Food (non-poultry) | R28: mcr-1.1 | T28: blaCTX-M-55 | W28: 197 | X28: 9 | Y28: aadA5 aph(3'')-Ib aph(6)-Id blaCTX-M-55 cirA_Q501Ter dfrA17 floR gyrA_D87N gyrA_S83L mcr-1.1 ompF_A233LfsTer7 parC_S80I sul2 tet(A) | Z28: 6448 | AA28: IncX4 | AC28: |mcr-1.1| | AD28: 100 | AE28: 0.14 | AF28: no | AG28: Yes
A29: PDT002834777.1 | B29: SAMN47476602 | C29: PRJNA1238567 | D29: GCA_051305755.1 | G29: GenBank assembly (no reads) | H29: PEco_TUN_65453 | I29: Tunisia | J29: Sousse | K29: 2023 | L29: 2023-07-26 | M29: Homo sapiens | N29: prosthetic joint infection | O29: Human | Q29: clinical | R29: mcr-1.1 | W29: 8 | X29: 5 | Y29: blaCMY-2 blaTEM-1 cirA_I160SfsTer34 floR gyrA_D87N gyrA_S83L mcr-1.1 parC_S80I sul2 | Z29: 224 | AA29: IncI2 | AC29: |mcr-1.1| | AD29: 100 | AE29: 0.21 | AF29: no | AG29: Yes
A30: PDT002807617.1 | B30: SAMN48947222 | C30: PRJNA1273464 | D30: GCA_050939535.1 | G30: GenBank assembly (no reads) | H30: PS51 | I30: Algeria | J30: Guelma | K30: 2022 | L30: 2022-12-01 | N30: Poultry farm | O30: Poultry | P30: Poultry farm environment | Q30: environmental/other | R30: mcr-1.1 | W30: 127 | X30: 2 | Y30: cirA_W243Ter gyrA_S83L mcr-1.1 tet(A) | Z30: 616 | AA30: IncI2 | AC30: |mcr-1.1| | AD30: 100 | AE30: 1.91 | AF30: no | AG30: Yes
A31: PDT002807616.1 | B31: SAMN48947229 | C31: PRJNA1273464 | D31: GCA_050939515.1 | G31: GenBank assembly (no reads) | H31: S11 | I31: Algeria | J31: Guelma | K31: 2022 | L31: 2022-02-01 | N31: Poultry farm | O31: Poultry | P31: Poultry farm environment | Q31: environmental/other | R31: mcr-1.1 | W31: 185 | X31: 2 | Y31: cyaA_S352T gyrA_D87N gyrA_S83L mcr-1.1 parC_S80I tet(A) | Z31: 93 | AA31: IncI2 (MOB-Recon bin) | AC31: |mcr-1.1| | AD31: 100 | AE31: 0.7 | AF31: no | AG31: Yes
A32: PDT002807611.1 | B32: SAMN48947223 | C32: PRJNA1273464 | D32: GCA_050939415.1 | G32: GenBank assembly (no reads) | H32: PS52 | I32: Algeria | J32: Guelma | K32: 2022 | L32: 2022-12-01 | N32: Poultry farm | O32: Poultry | P32: Poultry farm environment | Q32: environmental/other | R32: mcr-1.1 | W32: 232 | X32: 7 | Y32: blaTEM-1 catA1 cirA_Q42Ter dfrA14 gyrA_D87N gyrA_S83L mcr-1.1 mph(A) nfsA_Q195Ter nfsB_F167LfsTer11 parC_S80I sul2 tet(A) | Z32: 101 | AA32: IncI2 | AC32: |mcr-1.1| | AD32: 100 | AE32: 0.68 | AF32: no | AG32: Yes
A33: PDT002807609.1 | B33: SAMN48947225 | C33: PRJNA1273464 | D33: GCA_050939375.1 | G33: GenBank assembly (no reads) | H33: PS54 | I33: Algeria | J33: Guelma | K33: 2022 | L33: 2022-12-01 | N33: Poultry farm | O33: Poultry | P33: Poultry farm environment | Q33: environmental/other | R33: mcr-1.1 | W33: 146 | X33: 2 | Y33: cirA_W243Ter gyrA_S83L mcr-1.1 tet(A) | Z33: 616 | AA33: IncI2 | AC33: |mcr-1.1| | AD33: 100 | AE33: 0.75 | AF33: no | AG33: Yes
A34: PDT002807607.1 | B34: SAMN48947216 | C34: PRJNA1273464 | D34: GCA_050939335.1 | G34: GenBank assembly (no reads) | H34: PS45 | I34: Algeria | J34: Guelma | K34: 2022 | L34: 2022-12-01 | N34: Poultry farm | O34: Poultry | P34: Poultry farm environment | Q34: environmental/other | R34: mcr-1.1 | W34: 123 | X34: 2 | Y34: cirA_W243Ter gyrA_S83L mcr-1.1 tet(A) | Z34: 616 | AA34: IncI2 | AC34: |mcr-1.1| | AD34: 100 | AE34: 0.93 | AF34: no | AG34: Yes
A35: PDT002807606.1 | B35: SAMN48947220 | C35: PRJNA1273464 | D35: GCA_050939315.1 | G35: GenBank assembly (no reads) | H35: PS49 | I35: Algeria | J35: Guelma | K35: 2022 | L35: 2022-12-01 | N35: Poultry farm | O35: Poultry | P35: Poultry farm environment | Q35: environmental/other | R35: mcr-1.1 | W35: 164 | X35: 2 | Y35: cirA_W243Ter gyrA_S83L mcr-1.1 tet(A) | Z35: 616 | AA35: IncI2 (MOB-Recon bin) | AC35: |mcr-1.1| | AD35: 100 | AE35: 0.94 | AF35: no | AG35: Yes
A36: PDT002807605.1 | B36: SAMN48947210 | C36: PRJNA1273464 | D36: GCA_050939295.1 | G36: GenBank assembly (no reads) | H36: PS39 | I36: Algeria | J36: Guelma | K36: 2022 | L36: 2022-08-01 | N36: Poultry farm | O36: Poultry | P36: Poultry farm environment | Q36: environmental/other | R36: mcr-1.1 | W36: 97 | X36: 8 | Y36: aph(3'')-Ib aph(6)-Id blaTEM-1 cyaA_S352T dfrA7 gyrA_D87N gyrA_S83L mcr-1.1 parC_E84G parC_S80I parE_I355T sul1 sul2 tet(A) uhpT_E350Q | Z36: 354 | AA36: IncI2 | AC36: |mcr-1.1| | AD36: 100 | AE36: 0.6 | AF36: no | AG36: Yes
A37: PDT002807602.1 | B37: SAMN48947221 | C37: PRJNA1273464 | D37: GCA_050939235.1 | G37: GenBank assembly (no reads) | H37: PS50 | I37: Algeria | J37: Guelma | K37: 2022 | L37: 2022-12-01 | N37: Poultry farm | O37: Poultry | P37: Poultry farm environment | Q37: environmental/other | R37: mcr-1.1 | W37: 209 | X37: 7 | Y37: blaTEM-1 catA1 cirA_Q42Ter dfrA14 gyrA_D87N gyrA_S83L mcr-1.1 mph(A) nfsA_Q195Ter nfsB_F167LfsTer11 parC_S80I sul2 tet(A) | Z37: 101 | AA37: IncI2 | AC37: |mcr-1.1| | AD37: 100 | AE37: 1.01 | AF37: no | AG37: Yes
A38: PDT002807601.1 | B38: SAMN48947182 | C38: PRJNA1273464 | D38: GCA_050939215.1 | G38: GenBank assembly (no reads) | H38: PS02 | I38: Algeria | J38: Guelma | K38: 2022 | L38: 2022-05-01 | N38: Poultry farm | O38: Poultry | P38: Poultry farm environment | Q38: environmental/other | R38: mcr-1.1 | W38: 131 | X38: 6 | Y38: blaTEM-1 fosA4 gyrA_S83L mcr-1.1 mph(A) tet(A) tet(M) | Z38: 162 | AA38: IncI2 | AC38: |mcr-1.1| | AD38: 100 | AE38: 0.39 | AF38: no | AG38: Yes
A39: PDT002807600.1 | B39: SAMN48947184 | C39: PRJNA1273464 | D39: GCA_050939195.1 | G39: GenBank assembly (no reads) | H39: PS04 | I39: Algeria | J39: Guelma | K39: 2022 | L39: 2022-07-01 | N39: Poultry farm | O39: Poultry | P39: Poultry farm environment | Q39: environmental/other | R39: mcr-1.1 | W39: 179 | X39: 6 | Y39: aph(3'')-Ib aph(3')-Ia aph(6)-Id cirA_Q56Ter cyaA_S352T gyrA_D87N gyrA_S83L mcr-1.1 nfsA_Q26Ter nfsB_Q26Ter ompF_Q88Ter parC_E84K sul2 tet(B) | Z39: 117 | AA39: IncI2 | AC39: |mcr-1.1| | AD39: 100 | AE39: 0.73 | AF39: no | AG39: Yes
A40: PDT002807599.1 | B40: SAMN48947181 | C40: PRJNA1273464 | D40: GCA_050939175.1 | G40: GenBank assembly (no reads) | H40: PS01 | I40: Algeria | J40: Guelma | K40: 2022 | L40: 2022-05-01 | N40: Poultry farm | O40: Poultry | P40: Poultry farm environment | Q40: environmental/other | R40: mcr-1.1 | W40: 192 | X40: 12 | Y40: aadA1 aadA2 acrR_R162PfsTer24 aph(3')-Ia blaTEM-1 dfrA12 dfrA1 estX-3 gyrA_D87N gyrA_S83L mcr-1.1 mph(A) parC_S80I parE_S458A sul1 sul3 tet(A) | Z40: Untypeable | AA40: IncI2 | AB40: All seven alleles known but no ST assigned; likely novel ST (adk(6) fumC(11) gyrB(4) icd(8) mdh(276) purA(8) recA(6)). | AC40: |mcr-1.1| | AD40: 100 | AE40: 0.65 | AF40: no | AG40: Yes
...

Sheet SRA_runs_for_Galaxy
A1: Run | B1: BioSample | C1: Platform | D1: Layout | E1: Country | F1: Sector (derived) | G1: mcr variant(s) | H1: Use
A2: ERR13133321 | B2: SAMEA115598817 | C2: Illumina MiSeq | D2: PAIRED | E2: Egypt | F2: Human | G2: mcr-1.1 | H2: Short-read assembly (Shovill)
A3: ERR13133281 | B3: SAMEA115598777 | C3: Illumina MiSeq | D3: PAIRED | E3: Egypt | F3: Human | G3: mcr-1.1 | H3: Short-read assembly (Shovill)
A4: ERR15952774 | B4: SAMEA115952006 | C4: Illumina NovaSeq 6000 | D4: PAIRED | E4: Malawi | F4: Unspecified | G4: mcr-9 | H4: Short-read assembly (Shovill)
A5: SRR35975910 | B5: SAMN53123346 | C5: Illumina NovaSeq X | D5: PAIRED | E5: Tunisia | F5: Human | G5: mcr-1.1 | H5: Short-read assembly (Shovill)
A6: SRR35975911 | B6: SAMN53123345 | C6: Illumina NovaSeq X | D6: PAIRED | E6: Tunisia | F6: Human | G6: mcr-1.1 | H6: Short-read assembly (Shovill)
A7: SRR32898997 | B7: SAMN47596263 | C7: Illumina NovaSeq 6000 | D7: PAIRED | E7: Tunisia | F7: Food (non-poultry) | G7: mcr-1.1 | H7: Short-read assembly (Shovill)
A8: SRR32899008 | B8: SAMN47596259 | C8: Illumina NovaSeq 6000 | D8: PAIRED | E8: Tunisia | F8: Food (non-poultry) | G8: mcr-1.1 | H8: Short-read assembly (Shovill)
A9: SRR32899019 | B9: SAMN47596258 | C9: Illumina NovaSeq 6000 | D9: PAIRED | E9: Tunisia | F9: Food (non-poultry) | G9: mcr-1.1 | H9: Short-read assembly (Shovill)
A10: SRR33015174 | B10: SAMN40756789 | C10: Illumina MiSeq | D10: PAIRED | E10: Niger | F10: Human | G10: mcr-1 | H10: Short-read assembly (Shovill)
A11: ERR13952704 | B11: SAMEA114285223 | C11: Illumina NovaSeq 6000 | D11: PAIRED | E11: Malawi | F11: Unspecified | G11: mcr-9.1 | H11: Short-read assembly (Shovill)
A12: ERR13952550 | B12: SAMEA114284974 | C12: Illumina NovaSeq 6000 | D12: PAIRED | E12: Malawi | F12: Unspecified | G12: mcr-9.1 | H12: Short-read assembly (Shovill)
... A46: SRR25608269 | B46: SAMN36943049 | C46: ILLUMINA | D46: PAIRED | E46: South Africa | F46: Human | G46: mcr-1.1 | H46: Short-read assembly (Shovill)

Sheet Galaxy_results
A1: BioSample | B1: Galaxy input ID | C1: Galaxy arm | D1: Clean bases after fastp | E1: Est. depth (x, 5.1 Mb genome) | F1: Contigs (QUAST) | G1: Total length (bp) | H1: N50 (bp) | I1: GC (%) | J1: QC status | K1: mcr (PD) | L1: mcr (Galaxy AMRFinderPlus) | M1: AMRFinderPlus method | N1: % coverage | O1: % identity | P1: mcr contig | Q1: ABRicate NCBI mcr | R1: ABRicate ResFinder mcr | S1: PlasmidFinder replicon(s) on mcr contig | T1: MOB-Recon molecule | U1: MOB-Recon bin replicon(s) | V1: MOB-Recon relaxase(s) | W1: MOB-Recon bin size (bp) | X1: MLST ST (raw) | Y1: MLST alleles | Z1: All PlasmidFinder replicons in genome
A2: SAMEA123453495 | B2: GCA_988286365.1 | C2: B (ENA assembly) | E2: =IF(D2="","",D2/5100000) | J2: Not run (ENA upload; 10 contigs, 5.36 Mb) | K2: mcr-1.1 | L2: mcr-1.1 | M2: ALLELEX | N2: 100.00 | O2: 100.00 | P2: ENA|CGBNHJ010000002|CGBNHJ010000002.1 | Q2: mcr-1.1 | R2: mcr-1.1_1 | S2: IncI2_1_Delta | X2: 410 | Y2: adk(6) fumC(4) gyrB(12) icd(1) mdh(20) purA(18) recA(7) | Z2: IncFIB(AP001918)_1, IncFIC(FII)_1, IncI1_1_Alpha, IncI2_1_Delta
A3: SAMEA115598817 | B3: ERR13133321 | C3: A (reads, Shovill) | D3: 924335314 | E3: =IF(D3="","",D3/5100000) | F3: 183 | G3: 5264536 | H3: 147975 | I3: 50.7 | J3: Pass | K3: mcr-1.1 | L3: mcr-1.1 | M3: ALLELEX | N3: 100.00 | O3: 100.00 | P3: contig00041 | Q3: mcr-1.1 | R3: mcr-1.1_1 | S3: IncX4_1 | X3: 1196 | Y3: adk(6) fumC(6) gyrB(33) icd(26) mdh(11) purA(8) recA(2) | Z3: IncFIB(AP001918)_1, IncFIC(FII)_1, IncL/M(pOXA-48)_1_pOXA-48, IncR_1, IncX4_1
A4: SAMEA115598777 | B4: ERR13133281 | C4: A (reads, Shovill) | D4: 984175648 | E4: =IF(D4="","",D4/5100000) | F4: 236 | G4: 5389062 | H4: 105524 | I4: 50.4 | J4: Pass | K4: mcr-1.1 | L4: mcr-1.1 | M4: ALLELEX | N4: 100.00 | O4: 100.00 | P4: contig00093 | Q4: mcr-1.1 | R4: mcr-1.1_1 | S4: none | T4: chromosome | U4: - | V4: - | X4: 359 | Y4: adk(43) fumC(41) gyrB(15) icd(90) mdh(11) purA(8) recA(6) | Z4: IncFIB(AP001918)_1, IncFIC(FII)_1, IncI1_1_Alpha, IncX1_4, p0111_1
A5: SAMN54240895 | B5: GCA_056837985.1 | C5: B (GenBank assembly) | E5: =IF(D5="","",D5/5100000) | F5: 6 | G5: 5501346 | H5: 5011085 | I5: 50.48 | J5: Pass | K5: mcr-1.1 | L5: mcr-1.1 | M5: ALLELEX | N5: 100.00 | O5: 100.00 | P5: JBTFHJ010000006.1 | Q5: mcr-1.1 | R5: mcr-1.1_1 | S5: IncX4_1 | X5: 1011 | Y5: adk(6) fumC(4) gyrB(159) icd(44) mdh(112) purA(1) recA(17) | Z5: IncFIB(AP001918)_1, IncFIC(FII)_1, IncI1_1_Alpha, IncX4_1, p0111_1
A6: SAMN54240896 | B6: GCA_056837925.1 | C6: B (GenBank assembly) | E6: =IF(D6="","",D6/5100000) | F6: 4 | G6: 4954251 | H6: 4697231 | I6: 50.65 | J6: Pass | K6: mcr-1.1 | L6: mcr-1.1 | M6: ALLELEX | N6: 100.00 | O6: 100.00 | P6: JBTFHI010000003.1 | Q6: mcr-1.1 | R6: mcr-1.1_1 | S6: IncX4_1 | X6: 167 | Y6: adk(10) fumC(11) gyrB(4) icd(8) mdh(8) purA(13) recA(2) | Z6: IncFIB(AP001918)_1, IncQ1_1, IncX1_1, IncX4_1
A7: SAMN54240897 | B7: GCA_056837905.1 | C7: B (GenBank assembly) | E7: =IF(D7="","",D7/5100000) | F7: 6 | G7: 5223700 | H7: 4255832 | I7: 50.56 | J7: Pass | K7: mcr-1.1 | L7: mcr-1.1 | M7: ALLELEX | N7: 100.00 | O7: 100.00 | P7: JBTFHH010000004.1 | Q7: mcr-1.1 | R7: mcr-1.1_1 | S7: IncI2_1 | X7: 117 | Y7: adk(20) fumC(45) gyrB(41) icd(43) mdh(5) purA(32) recA(2) | Z7: IncFIB(AP001918)_1, IncFIC(FII)_1, IncI2_1
A8: SAMN54240898 | B8: GCA_056837885.1 | C8: B (GenBank assembly) | E8: =IF(D8="","",D8/5100000) | F8: 6 | G8: 5577124 | H8: 3305771 | I8: 50.52 | J8: Pass | K8: mcr-1.1 | L8: mcr-1.1 | M8: ALLELEX | N8: 100.00 | O8: 100.00 | P8: JBTFHG010000004.1 | Q8: mcr-1.1 | R8: mcr-1.1_1 | S8: IncI2_1_Delta | X8: - | Y8: adk(203) fumC(~210) gyrB(308) icd(25) mdh(4) purA(16) recA(19) | Z8: IncI2_1_Delta
A9: SAMN54240899 | B9: GCA_056837865.1 | C9: B (GenBank assembly) | E9: =IF(D9="","",D9/5100000) | F9: 5 | G9: 5412889 | H9: 5121332 | I9: 50.62 | J9: Pass | K9: mcr-1.1 | L9: mcr-1.1 | M9: ALLELEX | N9: 100.00 | O9: 100.00 | P9: JBTFHF010000004.1 | Q9: mcr-1.1 | R9: mcr-1.1_1 | S9: IncI2_1_Delta | X9: 69 | Y9: adk(21) fumC(35) gyrB(27) icd(6) mdh(5) purA(5) recA(4) | Z9: Col156_1, IncB/O/K/Z_2, IncFIA(HI1)_1_HI1, IncFIB(AP001918)_1, IncI2_1_Delta, IncY_1
A10: SAMN54240900 | B10: GCA_056837825.1 | C10: B (GenBank assembly) | E10: =IF(D10="","",D10/5100000) | F10: 4 | G10: 5296663 | H10: 5079085 | I10: 50.74 | J10: Pass | K10: mcr-1.1 | L10: mcr-1.1 | M10: ALLELEX | N10: 100.00 | O10: 100.00 | P10: JBTFHE010000003.1 | Q10: mcr-1.1 | R10: mcr-1.1_1 | S10: IncI2_1_Delta | X10: 9697 | Y10: adk(6) fumC(4) gyrB(4) icd(16) mdh(9) purA(8) recA(7) | Z10: IncFIB(AP001918)_1, IncFII_1, IncI2_1_Delta
A11: SAMN57053898 | B11: GCA_056711405.1 | C11: B (GenBank assembly) | E11: =IF(D11="","",D11/5100000) | F11: 6 | G11: 5297110 | H11: 5071810 | I11: 50.77 | J11: Pass | K11: mcr-1.1 | L11: mcr-1.1 | M11: ALLELEX | N11: 100.00 | O11: 100.00 | P11: JBWXYB010000003.1 | Q11: mcr-1.1 | R11: mcr-1.1_1 | S11: IncI2_1_Delta | X11: 9697 | Y11: adk(6) fumC(4) gyrB(4) icd(16) mdh(9) purA(8) recA(7) | Z11: IncFIB(AP001918)_1, IncFII_1, IncI2_1_Delta
A12: SAMN47585712 | B12: GCA_055786625.1 | C12: B (GenBank assembly) | E12: =IF(D12="","",D12/5100000) | F12: 5 | G12: 5172786 | H12: 4818742 | I12: 50.57 | J12: Pass | K12: mcr-1.1 | L12: mcr-1.1 | M12: ALLELEX | N12: 100.00 | O12: 100.00 | P12: JBVVBF010000002.1 | Q12: mcr-1.1 | R12: mcr-1.1_1 | S12: IncI2_1_Delta | X12: 162 | Y12: adk(9) fumC(65) gyrB(5) icd(1) mdh(9) purA(13) recA(6) | Z12: IncFIB(AP001918)_1, IncFIC(FII)_1, IncI1_1_Alpha, IncI2_1_Delta
A13: SAMN47585716 | B13: GCA_055786575.1 | C13: B (GenBank assembly) | E13: =IF(D13="","",D13/5100000) | F13: 5 | G13: 5011820 | H13: 4696956 | I13: 50.53 | J13: Pass | K13: mcr-1.1 | L13: mcr-1.1 | M13: ALLELEX | N13: 100.00 | O13: 100.00 | P13: JBVVBC010000001.1 | Q13: mcr-1.1 | R13: mcr-1.1_1 | S13: IncI2_1_Delta | X13: 10 | Y13: adk(10) fumC(11) gyrB(4) icd(8) mdh(8) purA(8) recA(2) | Z13: IncFIB(AP001918)_1, IncFIC(FII)_1, IncI1_1_Alpha, IncI2_1_Delta
A14: SAMN47585720 | B14: GCA_055786505.1 | C14: B (GenBank assembly) | E14: =IF(D14="","",D14/5100000) | F14: 4 | G14: 5306276 | H14: 4924089 | I14: 50.69 | J14: Pass | K14: mcr-1.1 | L14: mcr-1.1 | M14: ALLELEX | N14: 100.00 | O14: 100.00 | P14: JBVVAY010000004.1 | Q14: mcr-1.1 | R14: mcr-1.1_1 | S14: IncI2_1_Delta | X14: 162 | Y14: adk(9) fumC(65) gyrB(5) icd(1) mdh(9) purA(13) recA(6) | Z14: IncFIB(AP001918)_1, IncFIC(FII)_1, IncI1_1_Alpha, IncI2_1_Delta
A15: SAMEA120781931 | B15: GCA_977857605.1 | C15: B (GenBank assembly) | E15: =IF(D15="","",D15/5100000) | F15: 164 | G15: 4911609 | H15: 108383 | I15: 50.55 | J15: Pass | K15: mcr-1.1 | L15: mcr-1.1 | M15: ALLELEX | N15: 100.00 | O15: 100.00 | P15: CDWHEH010000028.1 | Q15: mcr-1.1 | R15: mcr-1.1_1 | S15: none | T15: plasmid | U15: IncHI1A,IncFIA | V15: MOBH | W15: 184243 | X15: 5625 | Y15: adk(10) fumC(7) gyrB(4) icd(10) mdh(12) purA(8) recA(86) | Z15: IncFIA(HI1)_1_HI1, IncFIB(K)_1_Kpn3, IncHI1A_1, IncHI1B(R27)_1_R27
A16: SAMN53123345 | B16: SRR35975911 | C16: A (reads, Shovill) | D16: 4645908303 | E16: =IF(D16="","",D16/5100000) | F16: 96 | G16: 5197667 | H16: 366000 | I16: 50.55 | J16: Pass | K16: mcr-1.1 | L16: mcr-1.1 | M16: ALLELEX | N16: 100.00 | O16: 100.00 | P16: contig00024 | Q16: mcr-1.1 | R16: mcr-1.1_1 | S16: IncX4_1 | X16: 1011 | Y16: adk(6) fumC(4) gyrB(159) icd(44) mdh(112) purA(1) recA(17) | Z16: IncFIB(AP001918)_1, IncL/M(pOXA-48)_1_pOXA-48, IncX1_1, IncX4_1
A17: SAMN53123346 | B17: SRR35975910 | C17: A (reads, Shovill) | D17: 2664629887 | E17: =IF(D17="","",D17/5100000) | F17: 178 | G17: 5279466 | H17: 111627 | I17: 50.4 | J17: Pass | K17: mcr-1.1 | L17: mcr-1.1 | M17: ALLELEX | N17: 100.00 | O17: 100.00 | P17: contig00043 | Q17: mcr-1.1 | R17: mcr-1.1_1 | S17: IncX4_1 | X17: - | Y17: adk(99) fumC(~1179) gyrB(33) icd(33) mdh(24) purA(8) recA(7) | Z17: IncFIB(AP001918)_1, IncFII(pRSB107)_1_pRSB107, IncI1_1_Alpha, IncI2_1_Delta, IncX4_1, p0111_1
A18: SAMN54331487 | B18: GCA_054353075.1 | C18: B (GenBank assembly) | E18: =IF(D18="","",D18/5100000) | F18: 177 | G18: 5053165 | H18: 75692 | I18: 50.51 | J18: Pass | K18: mcr-1.1 | L18: mcr-1.1 | M18: ALLELEX | N18: 100.00 | O18: 100.00 | P18: JBTHIR010000026.1 | Q18: mcr-1.1 | R18: mcr-1.1_1 | S18: IncI2_1 | X18: 10 | Y18: adk(10) fumC(11) gyrB(4) icd(8) mdh(8) purA(8) recA(2) | Z18: Col(BS512)_1, IncFIA_1, IncFIB(AP001918)_1, IncFIC(FII)_1, IncI1_1_Alpha, IncI2_1
A19: SAMEA115952006 | B19: ERR15952774 | C19: A (reads, Shovill) | D19: 450595590 | E19: =IF(D19="","",D19/5100000) | F19: 197 | G19: 5149345 | H19: 114466 | I19: 50.39 | J19: Pass | K19: mcr-9 | L19: mcr-9 | M19: BLASTX | N19: 100.00 | O19: 99.81 | P19: contig00088 | Q19: none | R19: mcr-9.1_1 | S19: none | T19: plasmid | U19: rep_cluster_1088,IncHI2A | V19: MOBH | W19: 332205 | X19: 401 | Y19: adk(1) fumC(107) gyrB(7) icd(11) mdh(7) purA(3) recA(7) | Z19: Col(IRGK)_1, IncHI2A_1, IncHI2_1
A20: SAMN49661573 | B20: GCA_053291725.1 | C20: B (GenBank assembly) | E20: =IF(D20="","",D20/5100000) | F20: 107 | G20: 5324071 | H20: 82543 | I20: 50.47 | J20: Pass | K20: mcr-1.1 | L20: mcr-1.1 | M20: ALLELEX | N20: 100.00 | O20: 100.00 | P20: JBRXEK010000027.1 | Q20: mcr-1.1 | R20: mcr-1.1_1 | S20: IncI2_1 | X20: 57 | Y20: adk(6) fumC(31) gyrB(5) icd(28) mdh(1) purA(1) recA(2) | Z20: IncI2_1, IncY_1
A21: SAMN44571232 | B21: GCA_053044365.1 | C21: B (GenBank assembly) | E21: =IF(D21="","",D21/5100000) | F21: 219 | G21: 5044812 | H21: 148104 | I21: 50.61 | J21: Pass | K21: mcr-1.1 | L21: mcr-1.1 | M21: ALLELEX | N21: 100.00 | O21: 100.00 | P21: JBIZWG010000030.1 | Q21: mcr-1.1 | R21: mcr-1.1_1 | S21: IncI2_1_Delta | X21: 155 | Y21: adk(6) fumC(4) gyrB(14) icd(16) mdh(24) purA(8) recA(14) | Z21: IncFIB(AP001918)_1, IncFIB(H89-PhagePlasmid)_1, IncFII(pCoo)_1_pCoo, IncFII(pRSB107)_1_pRSB107, IncI2_1_Delta, IncX1_1
A22: SAMN44571233 | B22: GCA_053044345.1 | C22: B (GenBank assembly) | E22: =IF(D22="","",D22/5100000) | F22: 217 | G22: 5044351 | H22: 148104 | I22: 50.62 | J22: Pass | K22: mcr-1.1 | L22: mcr-1.1 | M22: ALLELEX | N22: 100.00 | O22: 100.00 | P22: JBIZWH010000027.1 | Q22: mcr-1.1 | R22: mcr-1.1_1 | S22: IncI2_1_Delta | X22: 155 | Y22: adk(6) fumC(4) gyrB(14) icd(16) mdh(24) purA(8) recA(14) | Z22: IncFIB(AP001918)_1, IncFIB(H89-PhagePlasmid)_1, IncFII(pCoo)_1_pCoo, IncFII(pRSB107)_1_pRSB107, IncI2_1_Delta, IncX1_1
A23: SAMN44571236 | B23: GCA_053044255.1 | C23: B (GenBank assembly) | E23: =IF(D23="","",D23/5100000) | F23: 207 | G23: 5045982 | H23: 148713 | I23: 50.61 | J23: Pass | K23: mcr-1.1 | L23: mcr-1.1 | M23: ALLELEX | N23: 100.00 | O23: 100.00 | P23: JBIZWK010000029.1 | Q23: mcr-1.1 | R23: mcr-1.1_1 | S23: IncI2_1_Delta | X23: 155 | Y23: adk(6) fumC(4) gyrB(14) icd(16) mdh(24) purA(8) recA(14) | Z23: IncFIB(AP001918)_1, IncFIB(H89-PhagePlasmid)_1, IncFII(pCoo)_1_pCoo, IncFII(pRSB107)_1_pRSB107, IncI2_1_Delta, IncX1_1
A24: SAMN44571234 | B24: GCA_053044235.1 | C24: B (GenBank assembly) | E24: =IF(D24="","",D24/5100000) | F24: 205 | G24: 5046788 | H24: 148104 | I24: 50.62 | J24: Pass | K24: mcr-1.1 | L24: mcr-1.1 | M24: ALLELEX | N24: 100.00 | O24: 100.00 | P24: JBIZWI010000025.1 | Q24: mcr-1.1 | R24: mcr-1.1_1 | S24: IncI2_1_Delta | X24: 155 | Y24: adk(6) fumC(4) gyrB(14) icd(16) mdh(24) purA(8) recA(14) | Z24: IncFIB(AP001918)_1, IncFIB(H89-PhagePlasmid)_1, IncFII(pCoo)_1_pCoo, IncFII(pRSB107)_1_pRSB107, IncI2_1_Delta, IncX1_1
A25: SAMN44571235 | B25: GCA_053044225.1 | C25: B (GenBank assembly) | E25: =IF(D25="","",D25/5100000) | F25: 232 | G25: 5043971 | H25: 123136 | I25: 50.62 | J25: Pass | K25: mcr-1.1 | L25: mcr-1.1 | M25: ALLELEX | N25: 100.00 | O25: 100.00 | P25: JBIZWJ010000031.1 | Q25: mcr-1.1 | R25: mcr-1.1_1 | S25: IncI2_1_Delta | X25: 155 | Y25: adk(6) fumC(4) gyrB(14) icd(16) mdh(24) purA(8) recA(14) | Z25: IncFIB(AP001918)_1, IncFIB(H89-PhagePlasmid)_1, IncFII(pCoo)_1_pCoo, IncFII(pRSB107)_1_pRSB107, IncI2_1_Delta, IncX1_1
A26: SAMN47596258 | B26: SRR32899019 | C26: A (reads, Shovill) | D26: 1305007652 | E26: =IF(D26="","",D26/5100000) | F26: 280 | G26: 5626966 | H26: 113916 | I26: 50.27 | J26: Pass | K26: mcr-1.1 | L26: mcr-1 | M26: BLASTX | N26: 96.86 | O26: 100.00 | P26: contig00095 | Q26: mcr-1.1 | R26: mcr-1.1_1 | S26: none | T26: plasmid | U26: rep_cluster_1088,IncHI2A | V26: MOBH | W26: 257650 | X26: 3941 | Y26: adk(6) fumC(511) gyrB(4) icd(10) mdh(7) purA(8) recA(6) | Z26: IncB/O/K/Z_4, IncFIA_1, IncFIB(AP001918)_1, IncFIC(FII)_1, IncHI2A_1, IncHI2_1, IncI1_1_Alpha, IncI2_1_Delta, p0111_1
A27: SAMN47596259 | B27: SRR32899008 | C27: A (reads, Shovill) | D27: 2044251292 | E27: =IF(D27="","",D27/5100000) | F27: 282 | G27: 5621828 | H27: 115903 | I27: 50.28 | J27: Pass | K27: mcr-1.1 | L27: mcr-1 | M27: BLASTX | N27: 96.86 | O27: 100.00 | P27: contig00091 | Q27: mcr-1.1 | R27: mcr-1.1_1 | S27: none | T27: plasmid | U27: rep_cluster_1088,IncHI2A | V27: MOBH | W27: 256806 | X27: 3941 | Y27: adk(6) fumC(511) gyrB(4) icd(10) mdh(7) purA(8) recA(6) | Z27: IncB/O/K/Z_4, IncFIA_1, IncFIB(AP001918)_1, IncFIC(FII)_1, IncHI2A_1, IncHI2_1, IncI1_1_Alpha, IncI2_1_Delta, p0111_1
A28: SAMN47596263 | B28: SRR32898997 | C28: A (reads, Shovill) | D28: 3122382561 | E28: =IF(D28="","",D28/5100000) | F28: 215 | G28: 5401086 | H28: 218079 | I28: 50.41 | J28: Pass | K28: mcr-1.1 | L28: mcr-1.1 | M28: ALLELEX | N28: 100.00 | O28: 100.00 | P28: contig00032 | Q28: mcr-1.1 | R28: mcr-1.1_1 | S28: IncX4_1 | X28: 6448 | Y28: adk(6) fumC(4) gyrB(32) icd(1) mdh(9) purA(8) recA(6) | Z28: IncFIA_1, IncFIB(AP001918)_1, IncFIC(FII)_1, IncI1_1_Alpha, IncX4_1, p0111_1
A29: SAMN47476602 | B29: GCA_051305755.1 | C29: B (GenBank assembly) | E29: =IF(D29="","",D29/5100000) | F29: 8 | G29: 5349759 | H29: 4899910 | I29: 50.71 | J29: Pass | K29: mcr-1.1 | L29: mcr-1.1 | M29: ALLELEX | N29: 100.00 | O29: 100.00 | P29: JBPPKP010000005.1 | Q29: mcr-1.1 | R29: mcr-1.1_1 | S29: IncI2_1_Delta | X29: 224 | Y29: adk(6) fumC(4) gyrB(33) icd(16) mdh(11) purA(8) recA(6) | Z29: IncFIB(AP001918)_1, IncFII_1, IncI1_1_Alpha, IncI2_1_Delta
